Workbook

Sheet Front Page
B2: State of Affairs
B4: ="We are currently " & IF(C8-C7>0, "winning", IF(C8-C7<0, "losing", "tied by")) & " $" & TEXT(ROUND(ABS(C7-C8), 2), "0.00") -> We are currently losing $59.19
B5: Most Recent Round | C5: {=INDEX(Rounds!E:E,COUNTA(Rounds!E:E))} -> -0.65
B7: Starting Balance | C7: 375.01
B8: Current Balance | C8: {=index(Bets!P2:P1006, COUNT(Bets!P2:P1006))} -> 315.82
B9: Current ROI | C9: {=index(Bets!R3:R1006, COUNT(Bets!R3:R1006))} -> -0.15781333
B10: Live Bets | C10: =((C7-C8- ROUND(ABS(sum(Bets!O:O)), 2)))+ 1.25 -> 0
B11: Total Bets | C11: =COUNT(Bets!A:A) -> 440
B12: Average Bet | C12: =AVERAGE(Bets!L:L) -> 2.8014091
B13: Average Odds @ | C13: =AVERAGE(Bets!K:K) -> 2.0136884
B14: Average Result | C14: =AVERAGE(Bets!O:O) -> -0.13736364

Sheet Bets
A1: Index | B1: Date | C1: Matchday | D1: Home Team | E1: Home | F1: Away Team | G1: Away | H1: Bet Type | I1: Betting Option | J1: Supporting | K1: Odds | L1: Stake | M1: Result | N1: Payout | O1: Winnings | P1: Current Balance | Q1: Profit/Loss | R1: Return% | S1: Market | T1: Sport | U1: DOTW | V1: Notes
A2: 1 | B2: 45521 | C2: 1 | D2: Man Utd | E2: 1 | F2: Fulham | G2: 0 | H2: Full Time Result | I2: Man Utd | J2: Man Utd | K2: 1.57 | L2: 2 | M2: W | N2: 3.15 | O2: 1.15 | P2: =300.01-L2+N2 -> 301.16 | Q2: =P2-300.01 -> 1.15 | R2: =(P2-300)/300 -> 0.0038666667 | S2: EPL 24/25 | T2: Football | U2: =IF(B2<>"", TEXT(B2, "dddd"), "") -> Saturday | W2: =TRIM(CLEAN(H2)) -> Full Time Result
A3: 2 | B3: 45522 | C3: 1 | D3: Arsenal | E3: 2 | F3: Wolves | G3: 0 | H3: Asian Handicap | I3: Arsenal-1.5 | J3: Arsenal | K3: 1.625 | L3: 2 | M3: W | N3: 3.25 | O3: 1.25 | P3: =P2-L3+N3 -> 302.41 | Q3: =P3-300.01 -> 2.4 | R3: =(P3-300)/300 -> 0.0080333333 | S3: EPL 24/25 | T3: Football | U3: =IF(B3<>"", TEXT(B3, "dddd"), "") -> Sunday | W3: =TRIM(CLEAN(H3)) -> Asian Handicap
A4: 3 | B4: 45522 | C4: 1 | D4: West Ham | E4: 1 | F4: Villa | G4: 2 | H4: Full Time Result | I4: Draw | J4: Draw | K4: 3.5 | L4: 2 | M4: L | N4: 0 | O4: =N4-L4 -> -2 | P4: =P3-L4+N4 -> 300.41 | Q4: =P4-300.01 -> 0.4 | R4: =(P4-300)/300 -> 0.0013666667 | S4: EPL 24/25 | T4: Football | U4: =IF(B4<>"", TEXT(B4, "dddd"), "") -> Sunday | W4: =TRIM(CLEAN(H4)) -> Full Time Result
A5: 4 | B5: 45523 | C5: 1 | D5: Brentford | E5: 2 | F5: Palace | G5: 1 | H5: Double Chance | I5: Palace or Draw | J5: Palace | K5: 1.57 | L5: 2 | M5: L | N5: 0 | O5: =N5-L5 -> -2 | P5: =P4-L5+N5 -> 298.41 | Q5: =P5-300.01 -> -1.6 | R5: =(P5-300)/300 -> -0.0053 | S5: EPL 24/25 | T5: Football | U5: =IF(B5<>"", TEXT(B5, "dddd"), "") -> Monday | W5: =TRIM(CLEAN(H5)) -> Double Chance
A6: 5 | B6: 45524 | C6: 1 | D6: Leicester | E6: 1 | F6: Tottenham | G6: 1 | H6: Full Time Result | I6: Tottenham | J6: Tottenham | K6: 1.6 | L6: 2 | M6: L | N6: 0 | O6: =N6-L6 -> -2 | P6: =P5-L6+N6 -> 296.41 | Q6: =P6-300.01 -> -3.6 | R6: =(P6-300)/300 -> -0.011966667 | S6: EPL 24/25 | T6: Football | U6: =IF(B6<>"", TEXT(B6, "dddd"), "") -> Tuesday | W6: =TRIM(CLEAN(H6)) -> Full Time Result
A7: 6 | B7: 45529 | C7: 2 | D7: Brighton | E7: 2 | F7: Man Utd | G7: 1 | H7: Draw No Bet | I7: Man Utd | J7: Man Utd | K7: 1.83 | L7: 1.5 | M7: L | N7: 0 | O7: =N7-L7 -> -1.5 | P7: =P6-L7+N7 -> 294.91 | Q7: =P7-300.01 -> -5.1 | R7: =(P7-300)/300 -> -0.016966667 | S7: EPL 24/25 | T7: Football | U7: =IF(B7<>"", TEXT(B7, "dddd"), "") -> Sunday | W7: =TRIM(CLEAN(H7)) -> Draw No Bet
A8: 7 | B8: 45529 | C8: 2 | D8: Palace | E8: 0 | F8: West Ham | G8: 2 | H8: Draw No Bet | I8: Palace | J8: Palace | K8: 1.53 | L8: 0.5 | M8: L | N8: 0 | O8: =N8-L8 -> -0.5 | P8: =P7-L8+N8 -> 294.41 | Q8: =P8-300.01 -> -5.6 | R8: =(P8-300)/300 -> -0.018633333 | S8: EPL 24/25 | T8: Football | U8: =IF(B8<>"", TEXT(B8, "dddd"), "") -> Sunday | W8: =TRIM(CLEAN(H8)) -> Draw No Bet
A9: 8 | B9: 45529 | C9: 2 | D9: Fulham | E9: 2 | F9: Leicester | G9: 1 | H9: Draw No Bet | I9: Fulham | J9: Fulham | K9: 1.33 | L9: 1.5 | M9: W | N9: 2 | O9: =N9-L9 -> 0.5 | P9: =P8-L9+N9 -> 294.91 | Q9: =P9-300.01 -> -5.1 | R9: =(P9-300)/300 -> -0.016966667 | S9: EPL 24/25 | T9: Football | U9: =IF(B9<>"", TEXT(B9, "dddd"), "") -> Sunday | W9: =TRIM(CLEAN(H9)) -> Draw No Bet
A10: 9 | B10: 45529 | C10: 2 | D10: Man City | E10: 4 | F10: Ipswich | G10: 1 | H10: Handicap | I10: Man City -1 | J10: Man City | K10: 1.3 | L10: 3 | M10: W | N10: 3.9 | O10: =N10-L10 -> 0.9 | P10: =P9-L10+N10 -> 295.81 | Q10: =P10-300.01 -> -4.2 | R10: =(P10-300)/300 -> -0.013966667 | S10: EPL 24/25 | T10: Football | U10: =IF(B10<>"", TEXT(B10, "dddd"), "") -> Sunday | W10: =TRIM(CLEAN(H10)) -> Handicap
A11: 10 | B11: 45529 | C11: 2 | D11: Tottenham | E11: 4 | F11: Everton | G11: 0 | H11: Full Time Result | I11: Tottenham | J11: Tottenham | K11: 1.45 | L11: 0.5 | M11: W | N11: 0.73 | O11: =N11-L11 -> 0.23 | P11: =P10-L11+N11 -> 296.04 | Q11: =P11-300.01 -> -3.97 | R11: =(P11-300)/300 -> -0.0132 | S11: EPL 24/25 | T11: Football | U11: =IF(B11<>"", TEXT(B11, "dddd"), "") -> Sunday | W11: =TRIM(CLEAN(H11)) -> Full Time Result
A12: 11 | B12: 45530 | C12: 2 | D12: Bournemouth | E12: 1 | F12: Newcastle | G12: 1 | H12: Handicap | I12: Bournemouth +2 | J12: Bournemouth | K12: 1.22 | L12: 1.5 | M12: W | N12: 1.84 | O12: =N12-L12 -> 0.34 | P12: =P11-L12+N12 -> 296.38 | Q12: =P12-300.01 -> -3.63 | R12: =(P12-300)/300 -> -0.012066667 | S12: EPL 24/25 | T12: Football | U12: =IF(B12<>"", TEXT(B12, "dddd"), "") -> Monday | W12: =TRIM(CLEAN(H12)) -> Handicap
A13: 12 | B13: 45530 | C13: 2 | D13: Liverpool | E13: 2 | F13: Brentford | G13: 0 | H13: Handicap | I13: Liverpool -1 | J13: Liverpool | K13: 1.66 | L13: 1.5 | M13: W | N13: 2.5 | O13: =N13-L13 -> 1 | P13: =P12-L13+N13 -> 297.38 | Q13: =P13-300.01 -> -2.63 | R13: =(P13-300)/300 -> -0.0087333333 | S13: EPL 24/25 | T13: Football | U13: =IF(B13<>"", TEXT(B13, "dddd"), "") -> Monday | W13: =TRIM(CLEAN(H13)) -> Handicap
A14: 13 | B14: 45535 | C14: 3 | D14: Arsenal | E14: 1 | F14: Brighton | G14: 1 | H14: Full Time Result | I14: Arsenal | J14: Arsenal | K14: 1.33 | L14: 2 | M14: L | N14: 0 | O14: =N14-L14 -> -2 | P14: =P13-L14+N14 -> 295.38 | Q14: =P14-300.01 -> -4.63 | R14: =(P14-300)/300 -> -0.0154 | S14: EPL 24/25 | T14: Football | U14: =IF(B14<>"", TEXT(B14, "dddd"), "") -> Saturday | V14: Xanderdu middle debut | W14: =TRIM(CLEAN(H14)) -> Full Time Result
A15: 14 | B15: 45535 | C15: 3 | D15: Arsenal | E15: 1 | F15: Brighton | G15: 1 | H15: Handicap | I15: Brighton +3 | J15: Brighton | K15: 1.33 | L15: 2 | M15: W | N15: 2.67 | O15: =N15-L15 -> 0.67 | P15: =P14-L15+N15 -> 296.05 | Q15: =P15-300.01 -> -3.96 | R15: =(P15-300)/300 -> -0.013166667 | S15: EPL 24/25 | T15: Football | U15: =IF(B15<>"", TEXT(B15, "dddd"), "") -> Saturday | V15: Xanderdu middle debut | W15: =TRIM(CLEAN(H15)) -> Handicap
A16: 15 | B16: 45536 | C16: 3 | D16: Ipswich | E16: 1 | F16: Fulham | G16: 1 | H16: Handicap | I16: Ipswich +2 | J16: Ipswich | K16: 1.2 | L16: 0.5 | M16: W | N16: 0.6 | O16: =N16-L16 -> 0.1 | P16: =P15-L16+N16 -> 296.15 | Q16: =P16-300.01 -> -3.86 | R16: =(P16-300)/300 -> -0.012833333 | S16: EPL 24/25 | T16: Football | U16: =IF(B16<>"", TEXT(B16, "dddd"), "") -> Sunday | V16: Xanderdu middle 2 electric boogaloo | W16: =TRIM(CLEAN(H16)) -> Handicap
A17: 16 | B17: 45536 | C17: 3 | D17: Ipswich | E17: 1 | F17: Fulham | G17: 1 | H17: Handicap | I17: Fulham +1 | J17: Fulham | K17: 1.36 | L17: 0.5 | M17: W | N17: 0.69 | O17: =N17-L17 -> 0.19 | P17: =P16-L17+N17 -> 296.34 | Q17: =P17-300.01 -> -3.67 | R17: =(P17-300)/300 -> -0.0122 | S17: EPL 24/25 | T17: Football | U17: =IF(B17<>"", TEXT(B17, "dddd"), "") -> Sunday | V17: Xanderdu middle 2 electric boogaloo | W17: =TRIM(CLEAN(H17)) -> Handicap
A18: 17 | B18: 45536 | C18: 3 | D18: West Ham | E18: 1 | F18: Man City | G18: 3 | H18: Handicap | I18: Man City -1 | J18: Man City | K18: 1.9 | L18: 2 | M18: W | N18: 3.82 | O18: =N18-L18 -> 1.82 | P18: =P17-L18+N18 -> 298.16 | Q18: =P18-300.01 -> -1.85 | R18: =(P18-300)/300 -> -0.0061333333 | S18: EPL 24/25 | T18: Football | U18: =IF(B18<>"", TEXT(B18, "dddd"), "") -> Sunday | W18: =TRIM(CLEAN(H18)) -> Handicap
A19: 18 | B19: 45536 | C19: 3 | D19: Chelsea | E19: 1 | F19: Palace | G19: 1 | H19: Full Time Result | I19: Chelsea | J19: Chelsea | K19: 1.61 | L19: 3 | M19: L | N19: 0 | O19: =N19-L19 -> -3 | P19: =P18-L19+N19 -> 295.16 | Q19: =P19-300.01 -> -4.85 | R19: =(P19-300)/300 -> -0.016133333 | S19: EPL 24/25 | T19: Football | U19: =IF(B19<>"", TEXT(B19, "dddd"), "") -> Sunday | W19: =TRIM(CLEAN(H19)) -> Full Time Result
A20: 19 | B20: 45536 | D20: Multiple | F20: Multiple | H20: Relegation | I20: Everton | J20: Multiple | K20: 3 | L20: 4 | M20: L | N20: 3 | O20: =N20-L20 -> -1 | P20: =P19-L20+N20 -> 294.16 | Q20: =P20-300.01 -> -5.85 | R20: =(P20-300)/300 -> -0.019466667 | S20: EPL 24/25 | T20: Football | U20: =IF(B20<>"", TEXT(B20, "dddd"), "") -> Sunday | V20: Taken with the intent of cashing out at $4.80 or after 6 weeks | W20: =TRIM(CLEAN(H20)) -> Relegation
A21: 20 | B21: 45543 | C21: Null | D21: Mexico | E21: 3 | F21: New Zealand | G21: 0 | H21: Double Chance | I21: New Zealand or Draw | J21: New Zealand | K21: 3 | L21: 1 | M21: L | N21: 0 | O21: =N21-L21 -> -1 | P21: =P20-L21+N21 -> 293.16 | Q21: =P21-300.01 -> -6.85 | R21: =(P21-300)/300 -> -0.0228 | S21: World Cup OFC qualification | T21: Football | U21: =IF(B21<>"", TEXT(B21, "dddd"), "") -> Sunday | W21: =TRIM(CLEAN(H21)) -> Double Chance
A22: 21 | B22: 45550 | C22: 4 | D22: Villa | E22: 3 | F22: Everton | G22: 2 | H22: Full Time Result | I22: Villa | J22: Villa | K22: 1.5 | L22: 2 | M22: W | N22: 3 | O22: =N22-L22 -> 1 | P22: =P21-L22+N22 -> 294.16 | Q22: =P22-300.01 -> -5.85 | R22: =(P22-300)/300 -> -0.019466667 | S22: EPL 24/25 | T22: Football | U22: =IF(B22<>"", TEXT(B22, "dddd"), "") -> Sunday | W22: =TRIM(CLEAN(H22)) -> Full Time Result
A23: 22 | B23: 45550 | C23: 4 | D23: Man City | E23: 2 | F23: Brentford | G23: 1 | H23: Handicap | I23: Man City -1 | J23: Man City | K23: 1.5 | L23: 2 | M23: L | N23: 0 | O23: =N23-L23 -> -2 | P23: =P22-L23+N23 -> 292.16 | Q23: =P23-300.01 -> -7.85 | R23: =(P23-300)/300 -> -0.026133333 | S23: EPL 24/25 | T23: Football | U23: =IF(B23<>"", TEXT(B23, "dddd"), "") -> Sunday | W23: =TRIM(CLEAN(H23)) -> Handicap
A24: 23 | B24: 45550 | C24: 4 | D24: Liverpool | E24: 0 | F24: Forest | G24: 1 | H24: Handicap | I24: Liverpool -1 | J24: Liverpool | K24: 1.61 | L24: 2 | M24: L | N24: 0 | O24: =N24-L24 -> -2 | P24: =P23-L24+N24 -> 290.16 | Q24: =P24-300.01 -> -9.85 | R24: =(P24-300)/300 -> -0.0328 | S24: EPL 24/25 | T24: Football | U24: =IF(B24<>"", TEXT(B24, "dddd"), "") -> Sunday | W24: =TRIM(CLEAN(H24)) -> Handicap
A25: 24 | B25: 45550 | C25: 4 | D25: Palace | E25: 2 | F25: Leicester | G25: 2 | H25: Full Time Result | I25: Palace | J25: Palace | K25: 1.61 | L25: 2 | M25: L | N25: 0 | O25: =N25-L25 -> -2 | P25: =P24-L25+N25 -> 288.16 | Q25: =P25-300.01 -> -11.85 | R25: =(P25-300)/300 -> -0.039466667 | S25: EPL 24/25 | T25: Football | U25: =IF(B25<>"", TEXT(B25, "dddd"), "") -> Sunday | W25: =TRIM(CLEAN(H25)) -> Full Time Result
A26: 25 | B26: 45551 | C26: 4 | D26: Wolves | E26: 1 | F26: Newcastle | G26: 2 | H26: Double Chance | I26: Newcastle or Draw | J26: Newcastle | K26: 1.3 | L26: 2 | M26: W | N26: 2.6 | O26: =N26-L26 -> 0.6 | P26: =P25-L26+N26 -> 288.76 | Q26: =P26-300.01 -> -11.25 | R26: =(P26-300)/300 -> -0.037466667 | S26: EPL 24/25 | T26: Football | U26: =IF(B26<>"", TEXT(B26, "dddd"), "") -> Monday | W26: =TRIM(CLEAN(H26)) -> Double Chance
A27: 26 | B27: 45557 | C27: 5 | D27: Villa | E27: 3 | F27: Wolves | G27: 1 | H27: Full Time Result | I27: Villa | J27: Villa | K27: 1.57 | L27: 2 | M27: W | N27: 3.15 | O27: =N27-L27 -> 1.15 | P27: =P26-L27+N27 -> 289.91 | Q27: =P27-300.01 -> -10.1 | R27: =(P27-300)/300 -> -0.033633333 | S27: EPL 24/25 | T27: Football | U27: =IF(B27<>"", TEXT(B27, "dddd"), "") -> Sunday | W27: =TRIM(CLEAN(H27)) -> Full Time Result
A28: 27 | B28: 45557 | C28: 5 | D28: Tottenham | E28: 3 | F28: Brentford | G28: 1 | H28: Full Time Result | I28: Tottenham | J28: Tottenham | K28: 1.5 | L28: 2 | M28: W | N28: 3 | O28: =N28-L28 -> 1 | P28: =P27-L28+N28 -> 290.91 | Q28: =P28-300.01 -> -9.1 | R28: =(P28-300)/300 -> -0.0303 | S28: EPL 24/25 | T28: Football | U28: =IF(B28<>"", TEXT(B28, "dddd"), "") -> Sunday | W28: =TRIM(CLEAN(H28)) -> Full Time Result
A29: 28 | B29: 45557 | C29: 5 | D29: Leicester | E29: 1 | F29: Everton | G29: 1 | H29: Handicap | I29: Leicester +1 | J29: Leicester | K29: 1.4 | L29: 2 | M29: W | N29: 2.8 | O29: =N29-L29 -> 0.8 | P29: =P28-L29+N29 -> 291.71 | Q29: =P29-300.01 -> -8.3 | R29: =(P29-300)/300 -> -0.027633333 | S29: EPL 24/25 | T29: Football | U29: =IF(B29<>"", TEXT(B29, "dddd"), "") -> Sunday | W29: =TRIM(CLEAN(H29)) -> Handicap
A30: 29 | B30: 45557 | C30: 5 | D30: Palace | E30: 0 | F30: Man Utd | G30: 0 | H30: Handicap | I30: Man Utd +1 | J30: Man Utd | K30: 1.4 | L30: 2 | M30: W | N30: 2.8 | O30: =N30-L30 -> 0.8 | P30: =P29-L30+N30 -> 292.51 | Q30: =P30-300.01 -> -7.5 | R30: =(P30-300)/300 -> -0.024966667 | S30: EPL 24/25 | T30: Football | U30: =IF(B30<>"", TEXT(B30, "dddd"), "") -> Sunday | W30: =TRIM(CLEAN(H30)) -> Handicap
A31: 30 | B31: 45558 | C31: 5 | D31: Man City | E31: 2 | F31: Arsenal | G31: 2 | H31: BTTS | I31: Yes | J31: Multiple | K31: 1.8 | L31: 2 | M31: W | N31: 3.6 | O31: =N31-L31 -> 1.6 | P31: =P30-L31+N31 -> 294.11 | Q31: =P31-300.01 -> -5.9 | R31: =(P31-300)/300 -> -0.019633333 | S31: EPL 24/25 | T31: Football | U31: =IF(B31<>"", TEXT(B31, "dddd"), "") -> Monday | W31: =TRIM(CLEAN(H31)) -> BTTS
A32: 31 | B32: 45564 | C32: 6 | D32: Everton | E32: 2 | F32: Palace | G32: 1 | H32: Handicap | I32: Everton +1 | J32: Everton | K32: 1.5 | L32: 2 | M32: W | N32: 3 | O32: =N32-L32 -> 1 | P32: =P31-L32+N32 -> 295.11 | Q32: =P32-300.01 -> -4.9 | R32: =(P32-300)/300 -> -0.0163 | S32: EPL 24/25 | T32: Football | U32: =IF(B32<>"", TEXT(B32, "dddd"), "") -> Sunday | W32: =TRIM(CLEAN(H32)) -> Handicap
A33: 32 | B33: 45564 | C33: 6 | D33: Arsenal | E33: 4 | F33: Leicester | G33: 2 | H33: Handicap | I33: Arsenal-1 | J33: Arsenal | K33: 1.53 | L33: 2 | M33: W | N33: 3.07 | O33: =N33-L33 -> 1.07 | P33: =P32-L33+N33 -> 296.18 | Q33: =P33-300.01 -> -3.83 | R33: =(P33-300)/300 -> -0.012733333 | S33: EPL 24/25 | T33: Football | U33: =IF(B33<>"", TEXT(B33, "dddd"), "") -> Sunday | W33: =TRIM(CLEAN(H33)) -> Handicap
... A42: 41 | B42: 45572 | C42: 7 | D42: Brighton | E42: 3 | F42: Tottenham | G42: 2 | H42: BTTS | I42: Yes | J42: Multiple | K42: 1.36 | L42: 2 | M42: W | N42: 2.73 | O42: =N42-L42 -> 0.73 | P42: =P41-L42+N42 -> 292.27 | Q42: =P42-300.01 -> -7.74 | R42: =(P42-300)/300 -> -0.025766667 | S42: EPL 24/25 | T42: Football | U42: =IF(B42<>"", TEXT(B42, "dddd"), "") -> Monday | W42: =TRIM(CLEAN(H42)) -> BTTS
A43: 42 | B43: 45576 | C43: Null | D43: New Zealand | E43: 3 | F43: Tahiti | G43: 0 | H43: Handicap | I43: New Zealand -2 | J43: New Zealand | K43: 1.36 | L43: 2 | M43: W | N43: 2.73 | O43: =N43-L43 -> 0.73 | P43: =P42-L43+N43 -> 293 | Q43: =P43-300.01 -> -7.01 | R43: =(P43-300)/300 -> -0.023333333 | S43: World Cup OFC qualification | T43: Football | U43: =IF(B43<>"", TEXT(B43, "dddd"), "") -> Friday | W43: =TRIM(CLEAN(H43)) -> Handicap
A44: 43 | B44: 45576 | C44: Null | D44: New Zealand | E44: 3 | F44: Tahiti | G44: 0 | H44: Handicap | I44: New Zealand -4 | J44: New Zealand | K44: 2.75 | L44: 1 | M44: L | N44: 0 | O44: =N44-L44 -> -1 | P44: =P43-L44+N44 -> 292 | Q44: =P44-300.01 -> -8.01 | R44: =(P44-300)/300 -> -0.026666667 | S44: World Cup OFC qualification | T44: Football | U44: =IF(B44<>"", TEXT(B44, "dddd"), "") -> Friday | W44: =TRIM(CLEAN(H44)) -> Handicap
A45: 44 | B45: 45579 | C45: Null | D45: New Zealand | E45: 3 | F45: Malaysia | G45: 0 | H45: Full Time Result | I45: New Zealand | J45: New Zealand | K45: 1.42 | L45: 2 | M45: W | N45: 2.84 | O45: =N45-L45 -> 0.84 | P45: =P44-L45+N45 -> 292.84 | Q45: =P45-300.01 -> -7.17 | R45: =(P45-300)/300 -> -0.023866667 | S45: World Cup OFC qualification | T45: Football | U45: =IF(B45<>"", TEXT(B45, "dddd"), "") -> Monday | W45: =TRIM(CLEAN(H45)) -> Full Time Result
A46: 45 | B46: 45585 | C46: 8 | D46: Fulham | E46: 1 | F46: Villa | G46: 3 | H46: BTTS | I46: Yes | J46: Multiple | K46: 1.61 | L46: 2 | M46: W | N46: 3.24 | O46: =N46-L46 -> 1.24 | P46: =P45-L46+N46 -> 294.08 | Q46: =P46-300.01 -> -5.93 | R46: =(P46-300)/300 -> -0.019733333 | S46: EPL 24/25 | T46: Football | U46: =IF(B46<>"", TEXT(B46, "dddd"), "") -> Sunday | W46: =TRIM(CLEAN(H46)) -> BTTS
A47: 46 | B47: 45585 | C47: 8 | D47: Man Utd | E47: 2 | F47: Brentford | G47: 1 | H47: Handicap | I47: Brentford +2 | J47: Brentford | K47: 1.44 | L47: 2 | M47: W | N47: 2.89 | O47: =N47-L47 -> 0.89 | P47: =P46-L47+N47 -> 294.97 | Q47: =P47-300.01 -> -5.04 | R47: =(P47-300)/300 -> -0.016766667 | S47: EPL 24/25 | T47: Football | U47: =IF(B47<>"", TEXT(B47, "dddd"), "") -> Sunday | W47: =TRIM(CLEAN(H47)) -> Handicap
A48: 47 | B48: 45585 | C48: 8 | D48: Bournemouth | E48: 2 | F48: Arsenal | G48: 0 | H48: Full Time Result | I48: Arsenal | J48: Arsenal | K48: 1.66 | L48: 2 | M48: L | N48: 0 | O48: =N48-L48 -> -2 | P48: =P47-L48+N48 -> 292.97 | Q48: =P48-300.01 -> -7.04 | R48: =(P48-300)/300 -> -0.023433333 | S48: EPL 24/25 | T48: Football | U48: =IF(B48<>"", TEXT(B48, "dddd"), "") -> Sunday | W48: =TRIM(CLEAN(H48)) -> Full Time Result
...

Sheet Leaderboard
E2: Notes | F2: Total Staked | G2: Result | H2: Returns
E3: John | F3: 145 | G3: 23.85 | H3: 170.1
E4: Richard | F4: 145 | G4: -4.8 | H4: 140.2
E5: Xander | F5: 145 | G5: -36.4 | H5: 108.6
E6: Grand Total | F6: 435 | G6: -17.35 | H6: 418.9

Sheet Copy of Pivot table
E2: Market | F2: SUM of Stake | G2: SUM of Winnings | H2: ROI
E3: EPL 24/25 | F3: 480 | G3: -63.48 | H3: =G3/F3 -> -0.13225
E4: EPL 25/26 | F4: 449 | G4: -29.65 | H4: =G4/F4 -> -0.066035635
E5: Grand Total | F5: 929 | G5: -93.13 | H5: =G5/F5 -> -0.10024758

Sheet Sheet10
A1: Away Team | B1: Total Staked | C1: Result | D1: ROI
A2: Villa | B2: 10 | C2: 8.85 | D2: 0.885
A3: Liverpool | B3: 5 | C3: 4 | D3: 0.8
A4: Leeds | B4: 5 | C4: 3.65 | D4: 0.73
A5: Man City | B5: 10 | C5: 6.7 | D5: 0.67
A6: West Ham | B6: 5 | C6: 3.35 | D6: 0.67
A7: Arsenal | B7: 20 | C7: 8.75 | D7: 0.4375
A8: Chelsea | B8: 5 | C8: 2 | D8: 0.4
A9: Forest | B9: 25 | C9: 2.9 | D9: 0.116
A10: Everton | B10: 20 | C10: 0.65 | D10: 0.0325
A11: Wolves | B11: 30 | C11: 0.05 | D11: 0.0016666667
A12: Fulham | B12: 20 | C12: -0.2 | D12: -0.01
A13: Brighton | B13: 25 | C13: -1 | D13: -0.04
... A22: Sunderland | B22: 5 | C22: -5 | D22: -1

Sheet Charts

Sheet Betting Habits

Sheet Rounds
A1: Matchday | B1: Total Bets | C1: W | D1: L | E1: Winnings | F1: %W | G1: %L | H1: Cum Bets | I1: Cum W | J1: Cum L | K1: Cum %W | L1: Cum %L | M1: Cum Winnings
A2: 1 | B2: =COUNTIF(Bets!C300:C601, A2) -> 3 | C2: =COUNTIFS(Bets!C300:C601, A2, Bets!M300:M601, "W") -> 1 | D2: =COUNTIFS(Bets!C300:C601, A2, Bets!M300:M601, "L") -> 1 | E2: =SUMIF(Bets!C300:C601, A2, Bets!O300:O601) -> -4.5 | F2: =IF(C2 > 0, C2 / B2, 0) -> 0.33333333 | G2: =IF(D2 > 0, D2 / B2, 0) -> 0.33333333 | H2: =sum($B$2:B2) -> 3 | I2: =sum($C$2:C2) -> 1 | J2: =sum($D$2:D2) -> 1 | K2: =IF(H2 > 0, I2 / H2, 0) -> 0.33333333 | L2: =IF(H2 > 0, J2 / H2, 0) -> 0.33333333 | M2: =sum($E$2:E2) -> -4.5
A3: 2 | B3: =COUNTIF(Bets!C301:C602, A3) -> 3 | C3: =COUNTIFS(Bets!C301:C602, A3, Bets!M301:M602, "W") -> 2 | D3: =COUNTIFS(Bets!C301:C602, A3, Bets!M301:M602, "L") -> 0 | E3: =SUMIF(Bets!C301:C602, A3, Bets!O301:O602) -> 5.3 | F3: =IF(C3 > 0, C3 / B3, 0) -> 0.66666667 | G3: =IF(D3 > 0, D3 / B3, 0) -> 0 | H3: =sum($B$2:B3) -> 6 | I3: =sum($C$2:C3) -> 3 | J3: =sum($D$2:D3) -> 1 | K3: =IF(H3 > 0, I3 / H3, 0) -> 0.5 | L3: =IF(H3 > 0, J3 / H3, 0) -> 0.16666667 | M3: =sum($E$2:E3) -> 0.8
A4: 3 | B4: =COUNTIF(Bets!C302:C603, A4) -> 3 | C4: =COUNTIFS(Bets!C302:C603, A4, Bets!M302:M603, "W") -> 1 | D4: =COUNTIFS(Bets!C302:C603, A4, Bets!M302:M603, "L") -> 2 | E4: =SUMIF(Bets!C302:C603, A4, Bets!O302:O603) -> -8.65 | F4: =IF(C4 > 0, C4 / B4, 0) -> 0.33333333 | G4: =IF(D4 > 0, D4 / B4, 0) -> 0.66666667 | H4: =sum($B$2:B4) -> 9 | I4: =sum($C$2:C4) -> 4 | J4: =sum($D$2:D4) -> 3 | K4: =IF(H4 > 0, I4 / H4, 0) -> 0.44444444 | L4: =IF(H4 > 0, J4 / H4, 0) -> 0.33333333 | M4: =sum($E$2:E4) -> -7.85
A5: 4 | B5: =COUNTIF(Bets!C303:C604, A5) -> 3 | C5: =COUNTIFS(Bets!C303:C604, A5, Bets!M303:M604, "W") -> 2 | D5: =COUNTIFS(Bets!C303:C604, A5, Bets!M303:M604, "L") -> 1 | E5: =SUMIF(Bets!C303:C604, A5, Bets!O303:O604) -> -1 | F5: =IF(C5 > 0, C5 / B5, 0) -> 0.66666667 | G5: =IF(D5 > 0, D5 / B5, 0) -> 0.33333333 | H5: =sum($B$2:B5) -> 12 | I5: =sum($C$2:C5) -> 6 | J5: =sum($D$2:D5) -> 4 | K5: =IF(H5 > 0, I5 / H5, 0) -> 0.5 | L5: =IF(H5 > 0, J5 / H5, 0) -> 0.33333333 | M5: =sum($E$2:E5) -> -8.85
A6: 5 | B6: =COUNTIF(Bets!C304:C605, A6) -> 3 | C6: =COUNTIFS(Bets!C304:C605, A6, Bets!M304:M605, "W") -> 3 | D6: =COUNTIFS(Bets!C304:C605, A6, Bets!M304:M605, "L") -> 0 | E6: =SUMIF(Bets!C304:C605, A6, Bets!O304:O605) -> 9.1 | F6: =IF(C6 > 0, C6 / B6, 0) -> 1 | G6: =IF(D6 > 0, D6 / B6, 0) -> 0 | H6: =sum($B$2:B6) -> 15 | I6: =sum($C$2:C6) -> 9 | J6: =sum($D$2:D6) -> 4 | K6: =IF(H6 > 0, I6 / H6, 0) -> 0.6 | L6: =IF(H6 > 0, J6 / H6, 0) -> 0.26666667 | M6: =sum($E$2:E6) -> 0.25
A7: 6 | B7: =COUNTIF(Bets!C305:C606, A7) -> 3 | C7: =COUNTIFS(Bets!C305:C606, A7, Bets!M305:M606, "W") -> 1 | D7: =COUNTIFS(Bets!C305:C606, A7, Bets!M305:M606, "L") -> 2 | E7: =SUMIF(Bets!C305:C606, A7, Bets!O305:O606) -> -7.25 | F7: =IF(C7 > 0, C7 / B7, 0) -> 0.33333333 | G7: =IF(D7 > 0, D7 / B7, 0) -> 0.66666667 | H7: =sum($B$2:B7) -> 18 | I7: =sum($C$2:C7) -> 10 | J7: =sum($D$2:D7) -> 6 | K7: =IF(H7 > 0, I7 / H7, 0) -> 0.55555556 | L7: =IF(H7 > 0, J7 / H7, 0) -> 0.33333333 | M7: =sum($E$2:E7) -> -7
A8: 7 | B8: =COUNTIF(Bets!C306:C607, A8) -> 3 | C8: =COUNTIFS(Bets!C306:C607, A8, Bets!M306:M607, "W") -> 2 | D8: =COUNTIFS(Bets!C306:C607, A8, Bets!M306:M607, "L") -> 1 | E8: =SUMIF(Bets!C306:C607, A8, Bets!O306:O607) -> 1 | F8: =IF(C8 > 0, C8 / B8, 0) -> 0.66666667 | G8: =IF(D8 > 0, D8 / B8, 0) -> 0.33333333 | H8: =sum($B$2:B8) -> 21 | I8: =sum($C$2:C8) -> 12 | J8: =sum($D$2:D8) -> 7 | K8: =IF(H8 > 0, I8 / H8, 0) -> 0.57142857 | L8: =IF(H8 > 0, J8 / H8, 0) -> 0.33333333 | M8: =sum($E$2:E8) -> -6
A9: 8 | B9: =COUNTIF(Bets!C307:C608, A9) -> 3 | C9: =COUNTIFS(Bets!C307:C608, A9, Bets!M307:M608, "W") -> 2 | D9: =COUNTIFS(Bets!C307:C608, A9, Bets!M307:M608, "L") -> 1 | E9: =SUMIF(Bets!C307:C608, A9, Bets!O307:O608) -> -1 | F9: =IF(C9 > 0, C9 / B9, 0) -> 0.66666667 | G9: =IF(D9 > 0, D9 / B9, 0) -> 0.33333333 | H9: =sum($B$2:B9) -> 24 | I9: =sum($C$2:C9) -> 14 | J9: =sum($D$2:D9) -> 8 | K9: =IF(H9 > 0, I9 / H9, 0) -> 0.58333333 | L9: =IF(H9 > 0, J9 / H9, 0) -> 0.33333333 | M9: =sum($E$2:E9) -> -7
A10: 9 | B10: =COUNTIF(Bets!C308:C609, A10) -> 3 | C10: =COUNTIFS(Bets!C308:C609, A10, Bets!M308:M609, "W") -> 3 | D10: =COUNTIFS(Bets!C308:C609, A10, Bets!M308:M609, "L") -> 0 | E10: =SUMIF(Bets!C308:C609, A10, Bets!O308:O609) -> 8.4 | F10: =IF(C10 > 0, C10 / B10, 0) -> 1 | G10: =IF(D10 > 0, D10 / B10, 0) -> 0 | H10: =sum($B$2:B10) -> 27 | I10: =sum($C$2:C10) -> 17 | J10: =sum($D$2:D10) -> 8 | K10: =IF(H10 > 0, I10 / H10, 0) -> 0.62962963 | L10: =IF(H10 > 0, J10 / H10, 0) -> 0.2962963 | M10: =sum($E$2:E10) -> 1.4
A11: 10 | B11: =COUNTIF(Bets!C309:C610, A11) -> 3 | C11: =COUNTIFS(Bets!C309:C610, A11, Bets!M309:M610, "W") -> 2 | D11: =COUNTIFS(Bets!C309:C610, A11, Bets!M309:M610, "L") -> 0 | E11: =SUMIF(Bets!C309:C610, A11, Bets!O309:O610) -> 6.5 | F11: =IF(C11 > 0, C11 / B11, 0) -> 0.66666667 | G11: =IF(D11 > 0, D11 / B11, 0) -> 0 | H11: =sum($B$2:B11) -> 30 | I11: =sum($C$2:C11) -> 19 | J11: =sum($D$2:D11) -> 8 | K11: =IF(H11 > 0, I11 / H11, 0) -> 0.63333333 | L11: =IF(H11 > 0, J11 / H11, 0) -> 0.26666667 | M11: =sum($E$2:E11) -> 7.9
A12: 11 | B12: =COUNTIF(Bets!C310:C611, A12) -> 3 | C12: =COUNTIFS(Bets!C310:C611, A12, Bets!M310:M611, "W") -> 1 | D12: =COUNTIFS(Bets!C310:C611, A12, Bets!M310:M611, "L") -> 1 | E12: =SUMIF(Bets!C310:C611, A12, Bets!O310:O611) -> -3.2 | F12: =IF(C12 > 0, C12 / B12, 0) -> 0.33333333 | G12: =IF(D12 > 0, D12 / B12, 0) -> 0.33333333 | H12: =sum($B$2:B12) -> 33 | I12: =sum($C$2:C12) -> 20 | J12: =sum($D$2:D12) -> 9 | K12: =IF(H12 > 0, I12 / H12, 0) -> 0.60606061 | L12: =IF(H12 > 0, J12 / H12, 0) -> 0.27272727 | M12: =sum($E$2:E12) -> 4.7
A13: 12 | B13: =COUNTIF(Bets!C311:C612, A13) -> 4 | C13: =COUNTIFS(Bets!C311:C612, A13, Bets!M311:M612, "W") -> 2 | D13: =COUNTIFS(Bets!C311:C612, A13, Bets!M311:M612, "L") -> 2 | E13: =SUMIF(Bets!C311:C612, A13, Bets!O311:O612) -> -0.7 | F13: =IF(C13 > 0, C13 / B13, 0) -> 0.5 | G13: =IF(D13 > 0, D13 / B13, 0) -> 0.5 | H13: =sum($B$2:B13) -> 37 | I13: =sum($C$2:C13) -> 22 | J13: =sum($D$2:D13) -> 11 | K13: =IF(H13 > 0, I13 / H13, 0) -> 0.59459459 | L13: =IF(H13 > 0, J13 / H13, 0) -> 0.2972973 | M13: =sum($E$2:E13) -> 4
... A27: 26 | B27: =COUNTIF(Bets!C325:C626, A27) -> 4 | C27: =COUNTIFS(Bets!C325:C626, A27, Bets!M325:M626, "W") -> 2 | D27: =COUNTIFS(Bets!C325:C626, A27, Bets!M325:M626, "L") -> 2 | E27: =SUMIF(Bets!C325:C626, A27, Bets!O325:O626) -> -0.65 | F27: =IF(C27 > 0, C27 / B27, 0) -> 0.5 | G27: =IF(D27 > 0, D27 / B27, 0) -> 0.5 | H27: =sum($B$2:B27) -> 87 | I27: =sum($C$2:C27) -> 43 | J27: =sum($D$2:D27) -> 37 | K27: =IF(H27 > 0, I27 / H27, 0) -> 0.49425287 | L27: =IF(H27 > 0, J27 / H27, 0) -> 0.42528736 | M27: =sum($E$2:E27) -> -10.9
